<sdf version='1.11'>
  <model name='sam_bot'>
    <link name='base_link'>
      <inertial>
        <pose>0.31373248067024662 0 -0.098709864301789241 0 0 0</pose>
        <mass>2.2439499999999999</mass>
        <inertia>
          <ixx>7.7400872650571539</ixx>
          <ixy>0</ixy>
          <ixz>0.079758255531540367</ixz>
          <iyy>8.2579235986653003</iyy>
          <iyz>0</iyz>
          <izz>0.72461933360814645</izz>
        </inertia>
      </inertial>
      <collision name='base_link_collision'>
        <pose>0 0 0 0 0 0</pose>
        <geometry>
          <box>
            <size>2 1 0.5</size>
          </box>
        </geometry>
        <surface>
          <contact>
            <ode/>
          </contact>
          <friction>
            <ode/>
          </friction>
        </surface>
      </collision>
      <collision name='base_link_fixed_joint_lump__lidar_link_collision_1'>
        <pose>0.5 0 0.28499999999999998 0 0 0</pose>
        <geometry>
          <cylinder>
            <length>0.070000000000000007</length>
            <radius>0.14999999999999999</radius>
          </cylinder>
        </geometry>
        <surface>
          <contact>
            <ode/>
          </contact>
          <friction>
            <ode/>
          </friction>
        </surface>
      </collision>
      <visual name='base_link_visual'>
        <pose>0 0 0 0 0 0</pose>
        <geometry>
          <box>
            <size>2 1 0.5</size>
          </box>
        </geometry>
        <material>
          <diffuse>0 0 1 1</diffuse>
          <ambient>0 0 1 1</ambient>
        </material>
      </visual>
      <visual name='base_link_fixed_joint_lump__front_caster_visual_1'>
        <pose>0.65400000000000003 0 -0.25 0 0 0</pose>
        <geometry>
          <sphere>
            <radius>0.20000000000000001</radius>
          </sphere>
        </geometry>
        <material>
          <diffuse>1 0 0 1</diffuse>
          <ambient>1 0 0 1</ambient>
        </material>
      </visual>
      <visual name='base_link_fixed_joint_lump__lidar_link_visual_2'>
        <pose>0.5 0 0.28499999999999998 0 0 0</pose>
        <geometry>
          <cylinder>
            <length>0.070000000000000007</length>
            <radius>0.14999999999999999</radius>
          </cylinder>
        </geometry>
        <material>
          <diffuse>0 1 0 1</diffuse>
          <ambient>0 1 0 1</ambient>
        </material>
      </visual>
      <sensor name='imu_sensor' type='imu'>
        <always_on>true</always_on>
        <topic>base_imu</topic>
        <visualize>true</visualize>
        <imu>
          <angular_velocity>
            <x>
              <noise type='gaussian'>
                <mean>0</mean>
                <stddev>0.00020000000000000001</stddev>
                <bias_mean>7.5000000000000002e-06</bias_mean>
                <bias_stddev>7.9999999999999996e-07</bias_stddev>
              </noise>
            </x>
            <y>
              <noise type='gaussian'>
                <mean>0</mean>
                <stddev>0.00020000000000000001</stddev>
                <bias_mean>7.5000000000000002e-06</bias_mean>
                <bias_stddev>7.9999999999999996e-07</bias_stddev>
              </noise>
            </y>
            <z>
              <noise type='gaussian'>
                <mean>0</mean>
                <stddev>0.00020000000000000001</stddev>
                <bias_mean>7.5000000000000002e-06</bias_mean>
                <bias_stddev>7.9999999999999996e-07</bias_stddev>
              </noise>
            </z>
          </angular_velocity>
          <linear_acceleration>
            <x>
              <noise type='gaussian'>
                <mean>0</mean>
                <stddev>0.017000000000000001</stddev>
                <bias_mean>0.10000000000000001</bias_mean>
                <bias_stddev>0.001</bias_stddev>
              </noise>
            </x>
            <y>
              <noise type='gaussian'>
                <mean>0</mean>
                <stddev>0.017000000000000001</stddev>
                <bias_mean>0.10000000000000001</bias_mean>
                <bias_stddev>0.001</bias_stddev>
              </noise>
            </y>
            <z>
              <noise type='gaussian'>
                <mean>0</mean>
                <stddev>0.017000000000000001</stddev>
                <bias_mean>0.10000000000000001</bias_mean>
                <bias_stddev>0.001</bias_stddev>
              </noise>
            </z>
          </linear_acceleration>
        </imu>
      </sensor>
      <sensor name='lidar' type='ray'>
        <topic>body_lidar</topic>
        <always_on>true</always_on>
        <visualize>true</visualize>
        <update_rate>5</update_rate>
        <lidar>
          <scan>
            <horizontal>
              <samples>640</samples>
              <resolution>1</resolution>
              <min_angle>-2.6179963000000002</min_angle>
              <max_angle>2.6179963000000002</max_angle>
            </horizontal>
            <vertical>
              <samples>16</samples>
              <min_angle>-0.261799</min_angle>
              <max_angle>0.261799</max_angle>
              <resolution>1</resolution>
            </vertical>
          </scan>
          <range>
            <min>0.12</min>
            <max>3.5</max>
            <resolution>0.014999999999999999</resolution>
          </range>
          <noise>
            <type>gaussian</type>
            <mean>0</mean>
            <stddev>0.01</stddev>
          </noise>
        </lidar>
        <pose>0.5 0 0.28499999999999998 0 0 0</pose>
      </sensor>
    </link>
    <joint name='drivewhl_l_joint' type='revolute'>
      <pose relative_to='base_link'>-0.75 0.59999999999999998 -0.050000000000000003 0 0 0</pose>
      <parent>base_link</parent>
      <child>drivewhl_l_link</child>
      <axis>
        <xyz>0 1 0</xyz>
        <limit>
          <lower>-inf</lower>
          <upper>inf</upper>
        </limit>
        <dynamics>
          <spring_reference>0</spring_reference>
          <spring_stiffness>0</spring_stiffness>
        </dynamics>
      </axis>
    </joint>
    <link name='drivewhl_l_link'>
      <pose relative_to='drivewhl_l_joint'>0 0 0 0 0 0</pose>
      <inertial>
        <pose>0 0 0 0 0 0</pose>
        <mass>1</mass>
        <inertia>
          <ixx>0.043333000000000003</ixx>
          <ixy>0</ixy>
          <ixz>0</ixz>
          <iyy>0.043333000000000003</iyy>
          <iyz>0</iyz>
          <izz>0.080000000000000002</izz>
        </inertia>
      </inertial>
      <collision name='drivewhl_l_link_fixed_joint_lump__collision_collision'>
        <pose>0 0 0 0 0 0</pose>
        <geometry>
          <cylinder>
            <length>0.20000000000000001</length>
            <radius>0.40000000000000002</radius>
          </cylinder>
        </geometry>
      </collision>
      <visual name='drivewhl_l_link_visual'>
        <pose>0 0 0 1.5707963267948959 0 0</pose>
        <geometry>
          <cylinder>
            <length>0.20000000000000001</length>
            <radius>0.40000000000000002</radius>
          </cylinder>
        </geometry>
        <material>
          <diffuse>0.625 0.625 0.625 1</diffuse>
          <ambient>0.625 0.625 0.625 1</ambient>
        </material>
      </visual>
    </link>
    <joint name='drivewhl_r_joint' type='revolute'>
      <pose relative_to='base_link'>-0.75 -0.59999999999999998 -0.050000000000000003 0 0 0</pose>
      <parent>base_link</parent>
      <child>drivewhl_r_link</child>
      <axis>
        <xyz>0 1 0</xyz>
        <limit>
          <lower>-inf</lower>
          <upper>inf</upper>
        </limit>
        <dynamics>
          <spring_reference>0</spring_reference>
          <spring_stiffness>0</spring_stiffness>
        </dynamics>
      </axis>
    </joint>
    <link name='drivewhl_r_link'>
      <pose relative_to='drivewhl_r_joint'>0 0 0 0 0 0</pose>
      <inertial>
        <pose>0 0 0 0 0 0</pose>
        <mass>1</mass>
        <inertia>
          <ixx>0.043333000000000003</ixx>
          <ixy>0</ixy>
          <ixz>0</ixz>
          <iyy>0.043333000000000003</iyy>
          <iyz>0</iyz>
          <izz>0.080000000000000002</izz>
        </inertia>
      </inertial>
      <collision name='drivewhl_r_link_fixed_joint_lump__collision_collision'>
        <pose>0 0 0 0 0 0</pose>
        <geometry>
          <cylinder>
            <length>0.20000000000000001</length>
            <radius>0.40000000000000002</radius>
          </cylinder>
        </geometry>
      </collision>
      <visual name='drivewhl_r_link_visual'>
        <pose>0 0 0 1.5707963267948959 0 0</pose>
        <geometry>
          <cylinder>
            <length>0.20000000000000001</length>
            <radius>0.40000000000000002</radius>
          </cylinder>
        </geometry>
        <material>
          <diffuse>0.625 0.625 0.625 1</diffuse>
          <ambient>0.625 0.625 0.625 1</ambient>
        </material>
      </visual>
    </link>
    <plugin name='gz::sim::systems::DiffDrive' filename='gz-sim-diff-drive-system'>
      <left_joint>drivewhl_l_joint</left_joint>
      <right_joint>drivewhl_r_joint</right_joint>
      <wheel_separation>1.2</wheel_separation>
      <wheel_radius>0.4</wheel_radius>
      <topic>cmd_vel</topic>
      <frame_id>odom</frame_id>
      <child_frame_id>base_link</child_frame_id>
    </plugin>
    <frame name='base_joint' attached_to='base_link'>
      <pose>0 0 -0.45000000000000001 0 0 0</pose>
    </frame>
    <frame name='base_footprint' attached_to='base_joint'>
      <pose>0 0 0 0 0 0</pose>
    </frame>
    <frame name='caster_joint' attached_to='base_link'>
      <pose>0.65400000000000003 0 -0.25 0 0 0</pose>
    </frame>
    <frame name='front_caster' attached_to='caster_joint'>
      <pose>0 0 0 0 0 0</pose>
    </frame>
    <frame name='lidar_joint' attached_to='base_link'>
      <pose>0.5 0 0.28499999999999998 0 0 0</pose>
    </frame>
    <frame name='lidar_link' attached_to='lidar_joint'>
      <pose>0 0 0 0 0 0</pose>
    </frame>
  </model>
</sdf>
