<?xml version="1.0" ?>
<!-- =================================================================================== -->
<!-- |    This document was autogenerated by xacro from diff_car_description.xacro     | -->
<!-- |    EDITING THIS FILE BY HAND IS NOT RECOMMENDED                                 | -->
<!-- =================================================================================== -->
<robot name="sam_bot">
  <!-- <link name="dummy_base"></link> -->
  <gazebo>
    <pose>0 0 0.45 0 0 0</pose>
  </gazebo>
  <!-- Robot Base -->
  <!-- <link name="dummy"/>  
<joint name="dummy_to_base_link=" type="fixed">  
    <parent link="dummy"/>  
     <child link="base_link"/>  
</joint> -->
  <link name="base_link">
    <visual>
      <geometry>
        <box size="2 1 0.75"/>
      </geometry>
      <material name="Cyan">
        <color rgba="0 0 1.0 1.0"/>
      </material>
    </visual>
    <inertial>
      <mass value="1.14395"/>
      <inertia ixx="0.095328999999999997" ixy="0" ixz="0" iyy="0.38131700000000002" iyz="0" izz="0.47664600000000001">
      </inertia>
    </inertial>
    <collision>
      <geometry>
        <box size="2 1 0.75"/>
      </geometry>
      <!-- <surface>
        <friction>
          <ode/>
        </friction>
        <bounce/>
        <contact/>
      </surface> -->
    </collision>
  </link>
  <!-- Robot Footprint -->
  <link name="base_footprint"/>
  <joint name="base_joint" type="fixed">
    <parent link="base_link"/>
    <child link="base_footprint"/>
    <origin rpy="0 0 0" xyz="0.0 0.0 -0.45"/>
  </joint>
  <link name="drivewhl_l_link">
    <visual>
      <origin rpy="1.5707963267948966 0 0" xyz="0 0 0"/>
      <geometry>
        <cylinder length="0.2" radius="0.4"/>
      </geometry>
      <material name="Gray">
        <color rgba="0.5 0.5 0.5 1.0"/>
      </material>
    </visual>
    <inertial>
      <mass value="1"/>
      <inertia ixx="0.043333000000000003" ixy="0" ixz="0" iyy="0.043333000000000003" iyz="0" izz="0.080000000000000002">
        </inertia>
    </inertial>
    <collision name="collision">
      <origin rpy="1.5707963267948966 0 0" xyz="0 0 0"/>
      <geometry>
        <cylinder length="0.2" radius="0.4"/>
      </geometry>
    </collision>
  </link>
  <joint name="drivewhl_l_joint" type="continuous">
    <parent link="base_link"/>
    <child link="drivewhl_l_link"/>
    <origin rpy="0 0 0" xyz="-0.75 0.6 -0.05"/>
    <axis xyz="0 1 0"/>
  </joint>
  <link name="drivewhl_r_link">
    <visual>
      <origin rpy="1.5707963267948966 0 0" xyz="0 0 0"/>
      <geometry>
        <cylinder length="0.2" radius="0.4"/>
      </geometry>
      <material name="Gray">
        <color rgba="0.5 0.5 0.5 1.0"/>
      </material>
    </visual>
    <inertial>
      <mass value="1"/>
      <inertia ixx="0.043333000000000003" ixy="0" ixz="0" iyy="0.043333000000000003" iyz="0" izz="0.080000000000000002">
        </inertia>
    </inertial>
    <collision name="collision">
      <origin rpy="1.5707963267948966 0 0" xyz="0 0 0"/>
      <geometry>
        <cylinder length="0.2" radius="0.4"/>
      </geometry>
    </collision>
  </link>
  <joint name="drivewhl_r_joint" type="continuous">
    <parent link="base_link"/>
    <child link="drivewhl_r_link"/>
    <origin rpy="0 0 0" xyz="-0.75 -0.6 -0.05"/>
    <axis xyz="0 1 0"/>
  </joint>
  <!-- Caster Wheel -->
  <link name="front_caster">
    <visual>
      <geometry>
        <sphere radius="0.07500000000000001"/>
      </geometry>
      <material name="Red">
        <color rgba="1.0 0 0 1.0"/>
      </material>
    </visual>
    <inertial>
      <mass value="1"/>
      <inertia ixx="0.016" ixy="0" ixz="0" iyy="0.016" iyz="0" izz="0.016">
      </inertia>
    </inertial>
    <collision>
      <geometry>
        <sphere radius="0.07500000000000001"/>
      </geometry>
    </collision>
  </link>
  <joint name="caster_joint" type="continuous">
    <parent link="base_link"/>
    <child link="front_caster"/>
    <origin rpy="0 0 0" xyz="0.654 0.0 -0.375"/>
  </joint>
  <link name="lidar_link">
    <inertial>
      <mass value="0.1"/>
      <inertia ixx="7.58" ixy="0" ixz="0" iyy="7.58" iyz="0" izz="0.000125">
    </inertia>
    </inertial>
    <visual>
      <geometry>
        <cylinder length="0.07" radius="0.15">
          </cylinder>
      </geometry>
      <material name="Green">
        <color rgba="0 1 0 1"/>
      </material>
    </visual>
    <collision>
      <geometry>
        <cylinder length="0.07" radius="0.15">
          </cylinder>
      </geometry>
    </collision>
  </link>
  <joint name="lidar_joint" type="fixed">
    <parent link="base_link"/>
    <child link="lidar_link"/>
    <origin rpy="0 0 0" xyz="0.25 0 0.41000000000000003"/>
  </joint>
  <!-- <sensor name='gpu_lidar'>
      <pose>0 0 0 0 0 0</pose>
      <topic>/lidar</topic>
      <update_rate>1</update_rate>
      <enable_metrics>false</enable_metrics>
      <lidar>
          <scan>
          <horizontal>
              <samples>640</samples>
              <resolution>1</resolution>
              <min_angle>-2.6179963000000002</min_angle>
              <max_angle>2.6179963000000002</max_angle>
          </horizontal>
          <vertical>
              <samples>16</samples>
              <min_angle>-0.261799</min_angle>
              <max_angle>0.261799</max_angle>
              <resolution>1</resolution>
          </vertical>
          </scan>
          <range>
          <min>0.080000000000000002</min>
          <max>10</max>
          <resolution>0.01</resolution>
          </range>
          <noise>
          <type>none</type>
          <mean>0</mean>
          <stddev>0</stddev>
          </noise>
          <visibility_mask>4294967295</visibility_mask>
      </lidar>
      </sensor>
      <enable_wind>false</enable_wind> -->
  <gazebo reference="lidar_link">
    <sensor name="lidar" type="gpu_lidar">
      <topic>base_lidar</topic>
      <always_on>true</always_on>
      <visualize>true</visualize>
      <update_rate>30</update_rate>
      <frame_id>lidar_link</frame_id>
      <lidar>
        <scan>
          <horizontal>
            <samples>640</samples>
            <resolution>1</resolution>
            <min_angle>-2.6179963000000002</min_angle>
            <max_angle>2.6179963000000002</max_angle>
          </horizontal>
          <vertical>
            <samples>16</samples>
            <min_angle>-0.261799</min_angle>
            <max_angle>0.261799</max_angle>
            <resolution>1</resolution>
          </vertical>
        </scan>
        <range>
          <min>0.120000</min>
          <max>3.5</max>
          <resolution>0.015000</resolution>
        </range>
        <noise>
          <type>gaussian</type>
          <mean>0.0</mean>
          <stddev>0.01</stddev>
        </noise>
      </lidar>
    </sensor>
  </gazebo>
  <gazebo>
    <plugin filename="gz-sim-diff-drive-system" name="gz::sim::systems::DiffDrive">
      <left_joint>drivewhl_l_joint</left_joint>
      <right_joint>drivewhl_r_joint</right_joint>
      <wheel_separation>1.2</wheel_separation>
      <wheel_radius>0.4</wheel_radius>
      <tf_topic>/diff_drive/tf</tf_topic>
      <topic>cmd_vel</topic>
      <odom_publish_frequency>30</odom_publish_frequency>
      <!-- <odom_topic>sam_bot/odom</odom_topic> -->
      <frame_id>odom</frame_id>
      <child_frame_id>base_link</child_frame_id>
    </plugin>
  </gazebo>
  <gazebo reference="base_link">
    <sensor name="imu_sensor" type="imu">
      <always_on>true</always_on>
      <topic>base_imu</topic>
      <visualize>true</visualize>
      <update_rate>30</update_rate>
      <imu>
        <angular_velocity>
          <x>
            <noise type="gaussian">
              <mean>0.0</mean>
              <stddev>2e-4</stddev>
              <bias_mean>0.0000075</bias_mean>
              <bias_stddev>0.0000008</bias_stddev>
            </noise>
          </x>
          <y>
            <noise type="gaussian">
              <mean>0.0</mean>
              <stddev>2e-4</stddev>
              <bias_mean>0.0000075</bias_mean>
              <bias_stddev>0.0000008</bias_stddev>
            </noise>
          </y>
          <z>
            <noise type="gaussian">
              <mean>0.0</mean>
              <stddev>2e-4</stddev>
              <bias_mean>0.0000075</bias_mean>
              <bias_stddev>0.0000008</bias_stddev>
            </noise>
          </z>
        </angular_velocity>
        <linear_acceleration>
          <x>
            <noise type="gaussian">
              <mean>0.0</mean>
              <stddev>1.7e-2</stddev>
              <bias_mean>0.1</bias_mean>
              <bias_stddev>0.001</bias_stddev>
            </noise>
          </x>
          <y>
            <noise type="gaussian">
              <mean>0.0</mean>
              <stddev>1.7e-2</stddev>
              <bias_mean>0.1</bias_mean>
              <bias_stddev>0.001</bias_stddev>
            </noise>
          </y>
          <z>
            <noise type="gaussian">
              <mean>0.0</mean>
              <stddev>1.7e-2</stddev>
              <bias_mean>0.1</bias_mean>
              <bias_stddev>0.001</bias_stddev>
            </noise>
          </z>
        </linear_acceleration>
      </imu>
    </sensor>
  </gazebo>
</robot>
